Workbook
Name UPDATE: 'Data Sheet'!$E$1

Sheet Profit & Loss
A1: ='Data Sheet'!B1 -> TATA MOTORS LTD | H1: =UPDATE | M1: SCREENER.IN
A3: Narration | B3: ='Data Sheet'!B16 -> 42460 | C3: ='Data Sheet'!C16 -> 42825 | D3: ='Data Sheet'!D16 -> 43190 | E3: ='Data Sheet'!E16 -> 43555 | F3: ='Data Sheet'!F16 -> 43921 | G3: ='Data Sheet'!G16 -> 44286 | H3: ='Data Sheet'!H16 -> 44651 | I3: ='Data Sheet'!I16 -> 45016 | ... K3: ='Data Sheet'!K16 -> 45747 | L3: Trailing | M3: Best Case | N3: Worst Case
A4: Sales | B4: ='Data Sheet'!B17 -> 273045.6 | C4: ='Data Sheet'!C17 -> 269692.51 | D4: ='Data Sheet'!D17 -> 291550.48 | E4: ='Data Sheet'!E17 -> 301938.4 | F4: ='Data Sheet'!F17 -> 261067.97 | G4: ='Data Sheet'!G17 -> 249794.75 | H4: ='Data Sheet'!H17 -> 278453.62 | I4: ='Data Sheet'!I17 -> 345966.97 | ... K4: ='Data Sheet'!K17 -> 439695 | L4: =SUM(Quarters!H4:K4) -> 441609 | M4: =$K4+M23*K4 -> 512017.04 | N4: =$K4+N23*L4 -> 445473.35
A5: Expenses | B5: =SUM('Data Sheet'!B18,'Data Sheet'!B20:B24, -1*'Data Sheet'!B19) -> 234650.35 | C5: =SUM('Data Sheet'!C18,'Data Sheet'!C20:C24, -1*'Data Sheet'!C19) -> 240103.82 | D5: =SUM('Data Sheet'!D18,'Data Sheet'!D20:D24, -1*'Data Sheet'!D19) -> 260092.8 | E5: =SUM('Data Sheet'!E18,'Data Sheet'!E20:E24, -1*'Data Sheet'!E19) -> 277274.07 | F5: =SUM('Data Sheet'!F18,'Data Sheet'!F20:F24, -1*'Data Sheet'!F19) -> 243080.9 | G5: =SUM('Data Sheet'!G18,'Data Sheet'!G20:G24, -1*'Data Sheet'!G19) -> 217507.32 | H5: =SUM('Data Sheet'!H18,'Data Sheet'!H20:H24, -1*'Data Sheet'!H19) -> 253733.53 | I5: =SUM('Data Sheet'!I18,'Data Sheet'!I20:I24, -1*'Data Sheet'!I19) -> 314151.17 | ... K5: =SUM('Data Sheet'!K18,'Data Sheet'!K20:K24, -1*'Data Sheet'!K19) -> 384479 | L5: =SUM(Quarters!H5:K5) -> 384424 | M5: =M4-M6 -> 445714.73 | N5: =N4-N6 -> 398338.79
A6: Operating Profit | B6: =B4-B5 -> 38395.25 | C6: =C4-C5 -> 29588.69 | D6: =D4-D5 -> 31457.68 | E6: =E4-E5 -> 24664.33 | F6: =F4-F5 -> 17987.07 | G6: =G4-G5 -> 32287.43 | H6: =H4-H5 -> 24720.09 | I6: =I4-I5 -> 31815.8 | ... K6: =K4-K5 -> 55216 | L6: =SUM(Quarters!H6:K6) -> 57185 | M6: =M4*M24 -> 66302.304 | N6: =N4*N24 -> 47134.558
A7: Other Income | B7: ='Data Sheet'!B25 -> -2669.62 | C7: ='Data Sheet'!C25 -> 1869.1 | D7: ='Data Sheet'!D25 -> 5932.73 | E7: ='Data Sheet'!E25 -> -26686.25 | F7: ='Data Sheet'!F25 -> 101.71 | G7: ='Data Sheet'!G25 -> -11117.83 | H7: ='Data Sheet'!H25 -> 2424.05 | I7: ='Data Sheet'!I25 -> 6663.97 | ... K7: ='Data Sheet'!K25 -> 11774 | L7: =SUM(Quarters!H7:K7) -> 6151 | M7: 0 | N7: 0
A8: Depreciation | B8: ='Data Sheet'!B26 -> 16710.78 | C8: ='Data Sheet'!C26 -> 17904.99 | D8: ='Data Sheet'!D26 -> 21553.59 | E8: ='Data Sheet'!E26 -> 23590.63 | F8: ='Data Sheet'!F26 -> 21425.43 | G8: ='Data Sheet'!G26 -> 23546.71 | H8: ='Data Sheet'!H26 -> 24835.69 | I8: ='Data Sheet'!I26 -> 24860.36 | ... K8: ='Data Sheet'!K26 -> 23256 | L8: =SUM(Quarters!H8:K8) -> 23273 | M8: =+$L8 -> 23273 | N8: =+$L8 -> 23273
A9: Interest | B9: ='Data Sheet'!B27 -> 4889.08 | C9: ='Data Sheet'!C27 -> 4238.01 | D9: ='Data Sheet'!D27 -> 4681.79 | E9: ='Data Sheet'!E27 -> 5758.6 | F9: ='Data Sheet'!F27 -> 7243.33 | G9: ='Data Sheet'!G27 -> 8097.17 | H9: ='Data Sheet'!H27 -> 9311.86 | I9: ='Data Sheet'!I27 -> 10225.48 | ... K9: ='Data Sheet'!K27 -> 5083 | L9: =SUM(Quarters!H9:K9) -> 6317 | M9: =+$L9 -> 6317 | N9: =+$L9 -> 6317
A10: Profit before tax | B10: ='Data Sheet'!B28 -> 14125.77 | C10: ='Data Sheet'!C28 -> 9314.79 | D10: ='Data Sheet'!D28 -> 11155.03 | E10: ='Data Sheet'!E28 -> -31371.15 | F10: ='Data Sheet'!F28 -> -10579.98 | G10: ='Data Sheet'!G28 -> -10474.28 | H10: ='Data Sheet'!H28 -> -7003.41 | I10: ='Data Sheet'!I28 -> 3393.93 | ... K10: ='Data Sheet'!K28 -> 38651 | L10: =SUM(Quarters!H10:K10) -> 33746 | M10: =M6+M7-SUM(M8:M9) -> 36712.304 | N10: =N6+N7-SUM(N8:N9) -> 17544.558
A11: Tax | B11: ='Data Sheet'!B29 -> 3025.05 | C11: ='Data Sheet'!C29 -> 3251.23 | D11: ='Data Sheet'!D29 -> 4341.93 | E11: ='Data Sheet'!E29 -> -2437.45 | F11: ='Data Sheet'!F29 -> 395.25 | G11: ='Data Sheet'!G29 -> 2541.86 | H11: ='Data Sheet'!H29 -> 4231.29 | I11: ='Data Sheet'!I29 -> 704.06 | ... K11: ='Data Sheet'!K29 -> 10502 | L11: =SUM(Quarters!H11:K11) -> 10563 | M11: =IF($L10>0,$L11/$L10,0) -> 0.31301488 | N11: =IF($L10>0,$L11/$L10,0) -> 0.31301488
A12: Net profit | B12: ='Data Sheet'!B30 -> 11579.31 | C12: ='Data Sheet'!C30 -> 7454.36 | D12: ='Data Sheet'!D30 -> 8988.91 | E12: ='Data Sheet'!E30 -> -28826.23 | F12: ='Data Sheet'!F30 -> -12070.85 | G12: ='Data Sheet'!G30 -> -13451.39 | H12: ='Data Sheet'!H30 -> -11441.47 | I12: ='Data Sheet'!I30 -> 2414.29 | ... K12: ='Data Sheet'!K30 -> 27830 | L12: =SUM(Quarters!H12:K12) -> 22785 | M12: =M10-M11*M10 -> 25220.807 | N12: =N10-N11*N10 -> 12052.85
A13: EPS | B13: =IF('Data Sheet'!B93>0,B12/'Data Sheet'!B93,0) -> 40.105673 | C13: =IF('Data Sheet'!C93>0,C12/'Data Sheet'!C93,0) -> 25.817754 | D13: =IF('Data Sheet'!D93>0,D12/'Data Sheet'!D93,0) -> 31.132581 | E13: =IF('Data Sheet'!E93>0,E12/'Data Sheet'!E93,0) -> -99.838015 | F13: =IF('Data Sheet'!F93>0,F12/'Data Sheet'!F93,0) -> -39.076886 | G13: =IF('Data Sheet'!G93>0,G12/'Data Sheet'!G93,0) -> -40.512574 | H13: =IF('Data Sheet'!H93>0,H12/'Data Sheet'!H93,0) -> -34.454994 | I13: =IF('Data Sheet'!I93>0,I12/'Data Sheet'!I93,0) -> 7.2691115 | ... K13: =IF('Data Sheet'!K93>0,K12/'Data Sheet'!K93,0) -> 75.598294 | L13: =IF('Data Sheet'!$B6>0,'Profit & Loss'!L12/'Data Sheet'!$B6,0) -> 61.891168 | M13: =IF('Data Sheet'!$B6>0,'Profit & Loss'!M12/'Data Sheet'!$B6,0) -> 68.507579 | N13: =IF('Data Sheet'!$B6>0,'Profit & Loss'!N12/'Data Sheet'!$B6,0) -> 32.739302
A14: Price to earning | B14: =IF(B15>0,B15/B13,"") -> 9.639534 | C14: =IF(C15>0,C15/C13,"") -> 18.043785 | D14: =IF(D15>0,D15/D13,"") -> 10.498648 | E14: =IF(E15>0,E15/E13,"") -> -1.7453272 | F14: =IF(F15>0,F15/F13,"") -> -1.8182104 | G14: =IF(G15>0,G15/G13,"") -> -7.449539 | H14: =IF(H15>0,H15/H13,"") -> -12.588886 | I14: =IF(I15>0,I15/I13,"") -> 57.888781 | ... K14: =IF(K15>0,K15/K13,"") -> 8.9214976 | L14: =IF(L13>0,L15/L13,0) -> 10.862616 | M14: =M25 -> 22.045512 | N14: =N25 -> 10.862616
A15: Price | B15: ='Data Sheet'!B90 -> 386.6 | C15: ='Data Sheet'!C90 -> 465.85 | D15: ='Data Sheet'!D90 -> 326.85 | E15: ='Data Sheet'!E90 -> 174.25 | F15: ='Data Sheet'!F90 -> 71.05 | G15: ='Data Sheet'!G90 -> 301.8 | H15: ='Data Sheet'!H90 -> 433.75 | I15: ='Data Sheet'!I90 -> 420.8 | ... K15: ='Data Sheet'!K90 -> 674.45 | L15: ='Data Sheet'!B8 -> 672.3 | M15: =M13*M14 -> 1510.2847 | N15: =N13*N14 -> 355.63447
A17: RATIOS:
A18: Dividend Payout | B18: =IF('Data Sheet'!B30>0, 'Data Sheet'!B31/'Data Sheet'!B30, 0) -> 0.0058656345 | C18: =IF('Data Sheet'!C30>0, 'Data Sheet'!C31/'Data Sheet'!C30, 0) -> 0 | D18: =IF('Data Sheet'!D30>0, 'Data Sheet'!D31/'Data Sheet'!D30, 0) -> 0 | E18: =IF('Data Sheet'!E30>0, 'Data Sheet'!E31/'Data Sheet'!E30, 0) -> 0 | F18: =IF('Data Sheet'!F30>0, 'Data Sheet'!F31/'Data Sheet'!F30, 0) -> 0 | G18: =IF('Data Sheet'!G30>0, 'Data Sheet'!G31/'Data Sheet'!G30, 0) -> 0 | H18: =IF('Data Sheet'!H30>0, 'Data Sheet'!H31/'Data Sheet'!H30, 0) -> 0 | I18: =IF('Data Sheet'!I30>0, 'Data Sheet'!I31/'Data Sheet'!I30, 0) -> 0.31728583 | ... K18: =IF('Data Sheet'!K30>0, 'Data Sheet'!K31/'Data Sheet'!K30, 0) -> 0.079338843
A19: OPM | B19: =IF(B6>0,B6/B4,0) -> 0.14061845 | C19: =IF(C6>0,C6/C4,0) -> 0.10971269 | D19: =IF(D6>0,D6/D4,0) -> 0.10789788 | E19: =IF(E6>0,E6/E4,0) -> 0.081686629 | F19: =IF(F6>0,F6/F4,0) -> 0.068898034 | G19: =IF(G6>0,G6/G4,0) -> 0.12925584 | H19: =IF(H6>0,H6/H4,0) -> 0.088776328 | I19: =IF(I6>0,I6/I4,0) -> 0.091961958 | ... L19: =IF(L6>0,L6/L4,0) -> 0.12949238
G22: TRENDS: | H22: 10 YEARS | I22: 7 YEARS | J22: 5 YEARS | K22: 3 YEARS | L22: RECENT | M22: BEST | N22: WORST
G23: Sales Growth | H23: =IF(B4=0,"",POWER($K4/B4,1/9)-1) -> 0.05436433 | I23: =IF(D4=0,"",POWER($K4/D4,1/7)-1) -> 0.060452229 | J23: =IF(F4=0,"",POWER($K4/F4,1/5)-1) -> 0.1098891 | K23: =IF(H4=0,"",POWER($K4/H4, 1/3)-1) -> 0.16448229 | L23: =IF(ISERROR(MAX(IF(J4=0,"",(K4-J4)/J4),IF(K4=0,"",(L4-K4)/K4))),"",MAX(IF(J4=0,"",(K4-J4)/J4),IF(K4=0,"",(L4-K4)/K4))) -> 0.013084771 | M23: =MAX(K23:L23) -> 0.16448229 | N23: =MIN(H23:L23) -> 0.013084771
G24: OPM | H24: =IF(SUM(B4:$K$4)=0,"",SUMPRODUCT(B19:$K$19,B4:$K$4)/SUM(B4:$K$4)) -> 0.10935839 | I24: =IF(SUM(E4:$K$4)=0,"",SUMPRODUCT(E19:$K$19,E4:$K$4)/SUM(E4:$K$4)) -> 0.10580781 | J24: =IF(SUM(G4:$K$4)=0,"",SUMPRODUCT(G19:$K$19,G4:$K$4)/SUM(G4:$K$4)) -> 0.11548732 | K24: =IF(SUM(I4:$K$4)=0, "", SUMPRODUCT(I19:$K$19,I4:$K$4)/SUM(I4:$K$4)) -> 0.11876561 | L24: =L19 -> 0.12949238 | M24: =MAX(K24:L24) -> 0.12949238 | N24: =MIN(H24:L24) -> 0.10580781
G25: Price to Earning | H25: =IF(ISERROR(AVERAGEIF(B14:$L14,">0")),"",AVERAGEIF(B14:$L14,">0")) -> 18.052002 | I25: =IF(ISERROR(AVERAGEIF(E14:$L14,">0")),"",AVERAGEIF(E14:$L14,">0")) -> 22.045512 | J25: =IF(ISERROR(AVERAGEIF(G14:$L14,">0")),"",AVERAGEIF(G14:$L14,">0")) -> 22.045512 | K25: =IF(ISERROR(AVERAGEIF(I14:$L14,">0")),"",AVERAGEIF(I14:$L14,">0")) -> 22.045512 | L25: =L14 -> 10.862616 | M25: =MAX(K25:L25) -> 22.045512 | N25: =MIN(H25:L25) -> 10.862616

Sheet Quarters
A1: ='Profit & Loss'!A1 -> TATA MOTORS LTD | E1: =UPDATE | J1: SCREENER.IN
A3: Narration | B3: ='Data Sheet'!B41 -> 44926 | C3: ='Data Sheet'!C41 -> 45016 | D3: ='Data Sheet'!D41 -> 45107 | E3: ='Data Sheet'!E41 -> 45199 | F3: ='Data Sheet'!F41 -> 45291 | G3: ='Data Sheet'!G41 -> 45382 | H3: ='Data Sheet'!H41 -> 45473 | I3: ='Data Sheet'!I41 -> 45565 | ... K3: ='Data Sheet'!K41 -> 45747
A4: Sales | B4: ='Data Sheet'!B42 -> 88488.59 | C4: ='Data Sheet'!C42 -> 105932.35 | D4: ='Data Sheet'!D42 -> 102236 | E4: ='Data Sheet'!E42 -> 105129 | F4: ='Data Sheet'!F42 -> 110577 | G4: ='Data Sheet'!G42 -> 119033 | H4: ='Data Sheet'!H42 -> 108048 | I4: ='Data Sheet'!I42 -> 101450 | ... K4: ='Data Sheet'!K42 -> 119503
A5: Expenses | B5: ='Data Sheet'!B43 -> 77668.35 | C5: ='Data Sheet'!C43 -> 92817.95 | D5: ='Data Sheet'!D43 -> 89019 | E5: ='Data Sheet'!E43 -> 91362 | F5: ='Data Sheet'!F43 -> 95159 | G5: ='Data Sheet'!G43 -> 102348 | H5: ='Data Sheet'!H43 -> 92263 | I5: ='Data Sheet'!I43 -> 89291 | ... K5: ='Data Sheet'!K43 -> 102685
A6: Operating Profit | B6: ='Data Sheet'!B50 -> 10820.24 | C6: ='Data Sheet'!C50 -> 13114.4 | D6: ='Data Sheet'!D50 -> 13217 | E6: ='Data Sheet'!E50 -> 13767 | F6: ='Data Sheet'!F50 -> 15418 | G6: ='Data Sheet'!G50 -> 16685 | H6: ='Data Sheet'!H50 -> 15785 | I6: ='Data Sheet'!I50 -> 12159 | ... K6: ='Data Sheet'!K50 -> 16818
A7: Other Income | B7: ='Data Sheet'!B44 -> 1129.98 | C7: ='Data Sheet'!C44 -> 1452.86 | D7: ='Data Sheet'!D44 -> 895 | E7: ='Data Sheet'!E44 -> 1557 | F7: ='Data Sheet'!F44 -> 1604 | G7: ='Data Sheet'!G44 -> 1412 | H7: ='Data Sheet'!H44 -> 1747 | I7: ='Data Sheet'!I44 -> 1647 | ... K7: ='Data Sheet'!K44 -> 1057
A8: Depreciation | B8: ='Data Sheet'!B45 -> 6071.78 | C8: ='Data Sheet'!C45 -> 7050.2 | D8: ='Data Sheet'!D45 -> 6633 | E8: ='Data Sheet'!E45 -> 6637 | F8: ='Data Sheet'!F45 -> 6850 | G8: ='Data Sheet'!G45 -> 7143 | H8: ='Data Sheet'!H45 -> 6574 | I8: ='Data Sheet'!I45 -> 6005 | ... K8: ='Data Sheet'!K45 -> 5295
A9: Interest | B9: ='Data Sheet'!B46 -> 2675.83 | C9: ='Data Sheet'!C46 -> 2641.67 | D9: ='Data Sheet'!D46 -> 2615 | E9: ='Data Sheet'!E46 -> 2652 | F9: ='Data Sheet'!F46 -> 2485 | G9: ='Data Sheet'!G46 -> 1645 | H9: ='Data Sheet'!H46 -> 2088 | I9: ='Data Sheet'!I46 -> 2034 | ... K9: ='Data Sheet'!K46 -> 1076
A10: Profit before tax | B10: ='Data Sheet'!B47 -> 3202.61 | C10: ='Data Sheet'!C47 -> 4875.39 | D10: ='Data Sheet'!D47 -> 4864 | E10: ='Data Sheet'!E47 -> 6035 | F10: ='Data Sheet'!F47 -> 7687 | G10: ='Data Sheet'!G47 -> 9309 | H10: ='Data Sheet'!H47 -> 8870 | I10: ='Data Sheet'!I47 -> 5767 | ... K10: ='Data Sheet'!K47 -> 11504
A11: Tax | B11: ='Data Sheet'!B48 -> 262.83 | C11: ='Data Sheet'!C48 -> -620.65 | D11: ='Data Sheet'!D48 -> 1563 | E11: ='Data Sheet'!E48 -> 2203 | F11: ='Data Sheet'!F48 -> 542 | G11: ='Data Sheet'!G48 -> -8219 | H11: ='Data Sheet'!H48 -> 3178 | I11: ='Data Sheet'!I48 -> 2317 | ... K11: ='Data Sheet'!K48 -> 2948
A12: Net profit | B12: ='Data Sheet'!B49 -> 2957.71 | C12: ='Data Sheet'!C49 -> 5407.79 | D12: ='Data Sheet'!D49 -> 3203 | E12: ='Data Sheet'!E49 -> 3764 | F12: ='Data Sheet'!F49 -> 7025 | G12: ='Data Sheet'!G49 -> 17407 | H12: ='Data Sheet'!H49 -> 5566 | I12: ='Data Sheet'!I49 -> 3343 | ... K12: ='Data Sheet'!K49 -> 8470
A14: OPM | B14: =IF(B4>0,B6/B4,"") -> 0.12227836 | C14: =IF(C4>0,C6/C4,"") -> 0.12379976 | D14: =IF(D4>0,D6/D4,"") -> 0.12927931 | E14: =IF(E4>0,E6/E4,"") -> 0.1309534 | F14: =IF(F4>0,F6/F4,"") -> 0.13943225 | G14: =IF(G4>0,G6/G4,"") -> 0.14017121 | H14: =IF(H4>0,H6/H4,"") -> 0.14609248 | I14: =IF(I4>0,I6/I4,"") -> 0.11985214 | ... K14: =IF(K4>0,K6/K4,"") -> 0.14073287

Sheet Balance Sheet
A1: ='Profit & Loss'!A1 -> TATA MOTORS LTD | E1: =UPDATE | J1: SCREENER.IN
A3: Narration | B3: ='Data Sheet'!B56 -> 42460 | C3: ='Data Sheet'!C56 -> 42825 | D3: ='Data Sheet'!D56 -> 43190 | E3: ='Data Sheet'!E56 -> 43555 | F3: ='Data Sheet'!F56 -> 43921 | G3: ='Data Sheet'!G56 -> 44286 | H3: ='Data Sheet'!H56 -> 44651 | I3: ='Data Sheet'!I56 -> 45016 | ... K3: ='Data Sheet'!K56 -> 45747
A4: Equity Share Capital | B4: ='Data Sheet'!B57 -> 679.18 | C4: ='Data Sheet'!C57 -> 679.22 | D4: ='Data Sheet'!D57 -> 679.22 | E4: ='Data Sheet'!E57 -> 679.22 | F4: ='Data Sheet'!F57 -> 719.54 | G4: ='Data Sheet'!G57 -> 765.81 | H4: ='Data Sheet'!H57 -> 765.88 | I4: ='Data Sheet'!I57 -> 766.02 | ... K4: ='Data Sheet'!K57 -> 736
A5: Reserves | B5: ='Data Sheet'!B58 -> 78273.23 | C5: ='Data Sheet'!C58 -> 57382.67 | D5: ='Data Sheet'!D58 -> 94748.69 | E5: ='Data Sheet'!E58 -> 59500.34 | F5: ='Data Sheet'!F58 -> 62358.99 | G5: ='Data Sheet'!G58 -> 54480.91 | H5: ='Data Sheet'!H58 -> 43795.36 | I5: ='Data Sheet'!I58 -> 44555.77 | ... K5: ='Data Sheet'!K58 -> 115408
A6: Borrowings | B6: ='Data Sheet'!B59 -> 69359.96 | C6: ='Data Sheet'!C59 -> 78603.98 | D6: ='Data Sheet'!D59 -> 88950.47 | E6: ='Data Sheet'!E59 -> 106175.34 | F6: ='Data Sheet'!F59 -> 124787.64 | G6: ='Data Sheet'!G59 -> 142130.57 | H6: ='Data Sheet'!H59 -> 146449.03 | I6: ='Data Sheet'!I59 -> 134113.44 | ... K6: ='Data Sheet'!K59 -> 71540
A7: Other Liabilities | B7: ='Data Sheet'!B60 -> 114871.75 | C7: ='Data Sheet'!C60 -> 135914.49 | D7: ='Data Sheet'!D60 -> 142813.43 | E7: ='Data Sheet'!E60 -> 139348.59 | F7: ='Data Sheet'!F60 -> 132313.22 | G7: ='Data Sheet'!G60 -> 144192.62 | H7: ='Data Sheet'!H60 -> 138051.22 | I7: ='Data Sheet'!I60 -> 155239.2 | ... K7: ='Data Sheet'!K60 -> 189289
A8: Total | B8: ='Data Sheet'!B61 -> 263184.12 | C8: ='Data Sheet'!C61 -> 272580.36 | D8: ='Data Sheet'!D61 -> 327191.81 | E8: ='Data Sheet'!E61 -> 305703.49 | F8: ='Data Sheet'!F61 -> 320179.39 | G8: ='Data Sheet'!G61 -> 341569.91 | H8: ='Data Sheet'!H61 -> 329061.49 | I8: ='Data Sheet'!I61 -> 334674.43 | ... K8: ='Data Sheet'!K61 -> 376973
A10: Net Block | B10: ='Data Sheet'!B62 -> 107231.76 | C10: ='Data Sheet'!C62 -> 95944.08 | D10: ='Data Sheet'!D62 -> 121413.86 | E10: ='Data Sheet'!E62 -> 111234.47 | F10: ='Data Sheet'!F62 -> 127107.14 | G10: ='Data Sheet'!G62 -> 138707.61 | H10: ='Data Sheet'!H62 -> 138855.45 | I10: ='Data Sheet'!I62 -> 132079.76 | ... K10: ='Data Sheet'!K62 -> 115697
A11: Capital Work in Progress | B11: ='Data Sheet'!B63 -> 25918.94 | C11: ='Data Sheet'!C63 -> 33698.84 | D11: ='Data Sheet'!D63 -> 40033.5 | E11: ='Data Sheet'!E63 -> 31883.84 | F11: ='Data Sheet'!F63 -> 35622.29 | G11: ='Data Sheet'!G63 -> 20963.93 | H11: ='Data Sheet'!H63 -> 10251.09 | I11: ='Data Sheet'!I63 -> 14274.5 | ... K11: ='Data Sheet'!K63 -> 65806
A12: Investments | B12: ='Data Sheet'!B64 -> 23767.02 | C12: ='Data Sheet'!C64 -> 20337.92 | D12: ='Data Sheet'!D64 -> 20812.75 | E12: ='Data Sheet'!E64 -> 15770.72 | F12: ='Data Sheet'!F64 -> 16308.48 | G12: ='Data Sheet'!G64 -> 24620.28 | H12: ='Data Sheet'!H64 -> 29379.53 | I12: ='Data Sheet'!I64 -> 26379.16 | ... K12: ='Data Sheet'!K64 -> 35656
A13: Other Assets | B13: ='Data Sheet'!B65 -> 106266.4 | C13: ='Data Sheet'!C65 -> 122599.52 | D13: ='Data Sheet'!D65 -> 144931.7 | E13: ='Data Sheet'!E65 -> 146814.46 | F13: ='Data Sheet'!F65 -> 141141.48 | G13: ='Data Sheet'!G65 -> 157278.09 | H13: ='Data Sheet'!H65 -> 150575.42 | I13: ='Data Sheet'!I65 -> 161941.01 | ... K13: ='Data Sheet'!K65 -> 159814
A14: Total | B14: ='Data Sheet'!B66 -> 263184.12 | C14: ='Data Sheet'!C66 -> 272580.36 | D14: ='Data Sheet'!D66 -> 327191.81 | E14: ='Data Sheet'!E66 -> 305703.49 | F14: ='Data Sheet'!F66 -> 320179.39 | G14: ='Data Sheet'!G66 -> 341569.91 | H14: ='Data Sheet'!H66 -> 329061.49 | I14: ='Data Sheet'!I66 -> 334674.43 | ... K14: ='Data Sheet'!K66 -> 376973
A16: Working Capital | B16: =B13-B7 -> -8605.35 | C16: =C13-C7 -> -13314.97 | D16: =D13-D7 -> 2118.27 | E16: =E13-E7 -> 7465.87 | F16: =F13-F7 -> 8828.26 | G16: =G13-G7 -> 13085.47 | H16: =H13-H7 -> 12524.2 | I16: =I13-I7 -> 6701.81 | ... K16: =K13-K7 -> -29475
A17: Debtors | B17: ='Data Sheet'!B67 -> 13570.91 | C17: ='Data Sheet'!C67 -> 14075.55 | D17: ='Data Sheet'!D67 -> 19893.3 | E17: ='Data Sheet'!E67 -> 18996.17 | F17: ='Data Sheet'!F67 -> 11172.69 | G17: ='Data Sheet'!G67 -> 12679.08 | H17: ='Data Sheet'!H67 -> 12442.12 | I17: ='Data Sheet'!I67 -> 15737.97 | ... K17: ='Data Sheet'!K67 -> 13248
A18: Inventory | B18: ='Data Sheet'!B68 -> 32655.73 | C18: ='Data Sheet'!C68 -> 35085.31 | D18: ='Data Sheet'!D68 -> 42137.63 | E18: ='Data Sheet'!E68 -> 39013.73 | F18: ='Data Sheet'!F68 -> 37456.88 | G18: ='Data Sheet'!G68 -> 36088.59 | H18: ='Data Sheet'!H68 -> 35240.34 | I18: ='Data Sheet'!I68 -> 40755.39 | ... K18: ='Data Sheet'!K68 -> 47269
A20: Debtor Days | B20: =IF('Profit & Loss'!B4>0,'Balance Sheet'!B17/('Profit & Loss'!B4/365),0) -> 18.141227 | C20: =IF('Profit & Loss'!C4>0,'Balance Sheet'!C17/('Profit & Loss'!C4/365),0) -> 19.049753 | D20: =IF('Profit & Loss'!D4>0,'Balance Sheet'!D17/('Profit & Loss'!D4/365),0) -> 24.904965 | E20: =IF('Profit & Loss'!E4>0,'Balance Sheet'!E17/('Profit & Loss'!E4/365),0) -> 22.963631 | F20: =IF('Profit & Loss'!F4>0,'Balance Sheet'!F17/('Profit & Loss'!F4/365),0) -> 15.620575 | G20: =IF('Profit & Loss'!G4>0,'Balance Sheet'!G17/('Profit & Loss'!G4/365),0) -> 18.526667 | H20: =IF('Profit & Loss'!H4>0,'Balance Sheet'!H17/('Profit & Loss'!H4/365),0) -> 16.309265 | I20: =IF('Profit & Loss'!I4>0,'Balance Sheet'!I17/('Profit & Loss'!I4/365),0) -> 16.603779 | ... K20: =IF('Profit & Loss'!K4>0,'Balance Sheet'!K17/('Profit & Loss'!K4/365),0) -> 10.997441
A21: Inventory Turnover | B21: =IF('Balance Sheet'!B18>0,'Profit & Loss'!B4/'Balance Sheet'!B18,0) -> 8.3613381 | C21: =IF('Balance Sheet'!C18>0,'Profit & Loss'!C4/'Balance Sheet'!C18,0) -> 7.6867643 | D21: =IF('Balance Sheet'!D18>0,'Profit & Loss'!D4/'Balance Sheet'!D18,0) -> 6.9190052 | E21: =IF('Balance Sheet'!E18>0,'Profit & Loss'!E4/'Balance Sheet'!E18,0) -> 7.7392856 | F21: =IF('Balance Sheet'!F18>0,'Profit & Loss'!F4/'Balance Sheet'!F18,0) -> 6.9698269 | G21: =IF('Balance Sheet'!G18>0,'Profit & Loss'!G4/'Balance Sheet'!G18,0) -> 6.9217099 | H21: =IF('Balance Sheet'!H18>0,'Profit & Loss'!H4/'Balance Sheet'!H18,0) -> 7.9015588 | I21: =IF('Balance Sheet'!I18>0,'Profit & Loss'!I4/'Balance Sheet'!I18,0) -> 8.4888642 | ... K21: =IF('Balance Sheet'!K18>0,'Profit & Loss'!K4/'Balance Sheet'!K18,0) -> 9.3019738
A23: Return on Equity | B23: =IF(SUM('Balance Sheet'!B4:B5)>0,'Profit & Loss'!B12/SUM('Balance Sheet'!B4:B5),"") -> 0.14666189 | C23: =IF(SUM('Balance Sheet'!C4:C5)>0,'Profit & Loss'!C12/SUM('Balance Sheet'!C4:C5),"") -> 0.12838645 | D23: =IF(SUM('Balance Sheet'!D4:D5)>0,'Profit & Loss'!D12/SUM('Balance Sheet'!D4:D5),"") -> 0.094195818 | E23: =IF(SUM('Balance Sheet'!E4:E5)>0,'Profit & Loss'!E12/SUM('Balance Sheet'!E4:E5),"") -> -0.47900367 | F23: =IF(SUM('Balance Sheet'!F4:F5)>0,'Profit & Loss'!F12/SUM('Balance Sheet'!F4:F5),"") -> -0.19136226 | G23: =IF(SUM('Balance Sheet'!G4:G5)>0,'Profit & Loss'!G12/SUM('Balance Sheet'!G4:G5),"") -> -0.24347853 | H23: =IF(SUM('Balance Sheet'!H4:H5)>0,'Profit & Loss'!H12/SUM('Balance Sheet'!H4:H5),"") -> -0.25675834 | I23: =IF(SUM('Balance Sheet'!I4:I5)>0,'Profit & Loss'!I12/SUM('Balance Sheet'!I4:I5),"") -> 0.053269961 | ... K23: =IF(SUM('Balance Sheet'!K4:K5)>0,'Profit & Loss'!K12/SUM('Balance Sheet'!K4:K5),"") -> 0.23961634
A24: Return on Capital Emp | C24: =IF((B4+B5+B6+C4+C5+C6)>0,('Profit & Loss'!C10+'Profit & Loss'!C9)*2/(B4+B5+B6+C4+C5+C6),"") -> 0.095114631 | D24: =IF((C4+C5+C6+D4+D5+D6)>0,('Profit & Loss'!D10+'Profit & Loss'!D9)*2/(C4+C5+C6+D4+D5+D6),"") -> 0.098658176 | E24: =IF((D4+D5+D6+E4+E5+E6)>0,('Profit & Loss'!E10+'Profit & Loss'!E9)*2/(D4+D5+D6+E4+E5+E6),"") -> -0.14605144 | F24: =IF((E4+E5+E6+F4+F5+F6)>0,('Profit & Loss'!F10+'Profit & Loss'!F9)*2/(E4+E5+E6+F4+F5+F6),"") -> -0.018839365 | G24: =IF((F4+F5+F6+G4+G5+G6)>0,('Profit & Loss'!G10+'Profit & Loss'!G9)*2/(F4+F5+F6+G4+G5+G6),"") -> -0.012340819 | H24: =IF((G4+G5+G6+H4+H5+H6)>0,('Profit & Loss'!H10+'Profit & Loss'!H9)*2/(G4+G5+G6+H4+H5+H6),"") -> 0.011887353 | I24: =IF((H4+H5+H6+I4+I5+I6)>0,('Profit & Loss'!I10+'Profit & Loss'!I9)*2/(H4+H5+H6+I4+I5+I6),"") -> 0.073529898 | J24: =IF((I4+I5+I6+J4+J5+J6)>0,('Profit & Loss'!J10+'Profit & Loss'!J9)*2/(I4+I5+I6+J4+J5+J6),"") -> 0.19039483 | K24: =IF((J4+J5+J6+K4+K5+K6)>0,('Profit & Loss'!K10+'Profit & Loss'!K9)*2/(J4+J5+J6+K4+K5+K6),"") -> 0.23026014

Sheet Cash Flow
A1: ='Balance Sheet'!A1 -> TATA MOTORS LTD | E1: =UPDATE | J1: SCREENER.IN
A3: Narration | B3: ='Data Sheet'!B81 -> 42460 | C3: ='Data Sheet'!C81 -> 42825 | D3: ='Data Sheet'!D81 -> 43190 | E3: ='Data Sheet'!E81 -> 43555 | F3: ='Data Sheet'!F81 -> 43921 | G3: ='Data Sheet'!G81 -> 44286 | H3: ='Data Sheet'!H81 -> 44651 | I3: ='Data Sheet'!I81 -> 45016 | ... K3: ='Data Sheet'!K81 -> 45747
A4: Cash from Operating Activity | B4: ='Data Sheet'!B82 -> 37899.54 | C4: ='Data Sheet'!C82 -> 30199.25 | D4: ='Data Sheet'!D82 -> 23857.42 | E4: ='Data Sheet'!E82 -> 18890.75 | F4: ='Data Sheet'!F82 -> 26632.94 | G4: ='Data Sheet'!G82 -> 29000.51 | H4: ='Data Sheet'!H82 -> 14282.83 | I4: ='Data Sheet'!I82 -> 35388.01 | ... K4: ='Data Sheet'!K82 -> 63102
A5: Cash from Investing Activity | B5: ='Data Sheet'!B83 -> -36693.9 | C5: ='Data Sheet'!C83 -> -39571.4 | D5: ='Data Sheet'!D83 -> -25139.14 | E5: ='Data Sheet'!E83 -> -20878.07 | F5: ='Data Sheet'!F83 -> -33114.55 | G5: ='Data Sheet'!G83 -> -25672.5 | H5: ='Data Sheet'!H83 -> -4443.66 | I5: ='Data Sheet'!I83 -> -15417.17 | ... K5: ='Data Sheet'!K83 -> -49982
A6: Cash from Financing Activity | B6: ='Data Sheet'!B84 -> -3795.12 | C6: ='Data Sheet'!C84 -> 6205.3 | D6: ='Data Sheet'!D84 -> 2011.71 | E6: ='Data Sheet'!E84 -> 8830.37 | F6: ='Data Sheet'!F84 -> 3389.61 | G6: ='Data Sheet'!G84 -> 9904.2 | H6: ='Data Sheet'!H84 -> -3380.17 | I6: ='Data Sheet'!I84 -> -26242.9 | ... K6: ='Data Sheet'!K84 -> -18786
A7: Net Cash Flow | B7: ='Data Sheet'!B85 -> -2589.48 | C7: ='Data Sheet'!C85 -> -3166.85 | D7: ='Data Sheet'!D85 -> 729.99 | E7: ='Data Sheet'!E85 -> 6843.05 | F7: ='Data Sheet'!F85 -> -3092 | G7: ='Data Sheet'!G85 -> 13232.21 | H7: ='Data Sheet'!H85 -> 6459 | I7: ='Data Sheet'!I85 -> -6272.06 | ... K7: ='Data Sheet'!K85 -> -5666

Sheet Data Sheet
A1: COMPANY NAME | B1: TATA MOTORS LTD | E1: =IF(B2<>B3, "A NEW VERSION OF THE WORKSHEET IS AVAILABLE", "")
A2: LATEST VERSION | B2: 2.1 | E2: PLEASE DO NOT MAKE ANY CHANGES TO THIS SHEET
A3: CURRENT VERSION | B3: 2.1
A5: META
A6: Number of shares | B6: =IF(B9>0, B9/B8, 0) -> 368.14623
A7: Face Value | B7: 2
A8: Current Price | B8: 672.3
A9: Market Capitalization | B9: 247504.71
A15: PROFIT & LOSS
A16: Report Date | B16: 42460 | C16: 42825 | D16: 43190 | E16: 43555 | F16: 43921 | G16: 44286 | H16: 44651 | I16: 45016 | J16: 45382 | K16: 45747
A17: Sales | B17: 273045.6 | C17: 269692.51 | D17: 291550.48 | E17: 301938.4 | F17: 261067.97 | G17: 249794.75 | H17: 278453.62 | I17: 345966.97 | J17: 434016 | K17: 439695
A18: Raw Material Cost | B18: 166134.01 | C18: 173294.08 | D18: 187896.58 | E18: 194267.91 | F18: 164899.82 | G18: 153607.36 | H18: 179295.33 | I18: 231251.26 | J18: 274321 | K18: 268950
A19: Change in Inventory | B19: 2750.99 | C19: 7399.92 | D19: 2046.58 | E19: -2053.28 | F19: -2231.19 | G19: -4684.16 | H19: -1590.49 | I19: 4781.62 | J19: 1566 | K19: -2836
A20: Power and Fuel | B20: 1143.63 | C20: 1159.82 | D20: 1308.08 | E20: 1585.93 | F20: 1264.95 | G20: 1112.87 | H20: 2178.29 | I20: 2513.33 | J20: 2189 | K20: 2443
A21: Other Mfr. Exp | B21: 12101.53 | C21: 10067.37 | D21: 10971.66 | E21: 11694.54 | F21: 11541.51 | G21: 8273.17 | H21: 9427.38 | I21: 11765.97 | J21: 17446 | K21: 18813
A22: Employee Cost | B22: 28880.89 | C22: 28332.89 | D22: 30300.09 | E22: 33243.87 | F22: 30438.6 | G22: 27648.48 | H22: 30808.52 | I22: 33654.7 | J22: 41990 | K22: 47767
A23: Selling and admin | B23: 21991.9 | C23: 30039.38 | D23: 31004.58 | E23: 32719.8 | F23: 29248.32 | G23: 23015.79 | H23: 29205.4 | I23: 34839.19 | J23: 42765 | K23: 47099
A24: Other Expenses | B24: 7149.38 | C24: 4610.2 | D24: 658.39 | E24: 1708.74 | F24: 3456.51 | G24: -834.51 | H24: 1228.12 | I24: 4908.34 | J24: -953 | K24: -3429
A25: Other Income | B25: -2669.62 | C25: 1869.1 | D25: 5932.73 | E25: -26686.25 | F25: 101.71 | G25: -11117.83 | H25: 2424.05 | I25: 6663.97 | J25: 4792 | K25: 11774
A26: Depreciation | B26: 16710.78 | C26: 17904.99 | D26: 21553.59 | E26: 23590.63 | F26: 21425.43 | G26: 23546.71 | H26: 24835.69 | I26: 24860.36 | J26: 27239 | K26: 23256
A27: Interest | B27: 4889.08 | C27: 4238.01 | D27: 4681.79 | E27: 5758.6 | F27: 7243.33 | G27: 8097.17 | H27: 9311.86 | I27: 10225.48 | J27: 7594 | K27: 5083
... A30: Net profit | B30: 11579.31 | C30: 7454.36 | D30: 8988.91 | E30: -28826.23 | F30: -12070.85 | G30: -13451.39 | H30: -11441.47 | I30: 2414.29 | J30: 31399 | K30: 27830
A31: Dividend Amount | B31: 67.92 | I31: 766.02 | J31: 2301 | K31: 2208
A32: EBITDA | B32: =B30+B27+B29+B26 -> 36204.22 | C32: =C30+C27+C29+C26 -> 32848.59 | D32: =D30+D27+D29+D26 -> 39566.22 | E32: =E30+E27+E29+E26 -> -1914.45 | F32: =F30+F27+F29+F26 -> 16993.16 | G32: =G30+G27+G29+G26 -> 20734.35 | H32: =H30+H27+H29+H26 -> 26937.37 | I32: =I30+I27+I29+I26 -> 38204.19 | ... K32: =K30+K27+K29+K26 -> 66671
A40: Quarters
A41: Report Date | B41: 44926 | C41: 45016 | D41: 45107 | E41: 45199 | F41: 45291 | G41: 45382 | H41: 45473 | I41: 45565 | J41: 45657 | K41: 45747
A42: Sales | B42: 88488.59 | C42: 105932.35 | D42: 102236 | E42: 105129 | F42: 110577 | G42: 119033 | H42: 108048 | I42: 101450 | J42: 112608 | K42: 119503
A43: Expenses | B43: 77668.35 | C43: 92817.95 | D43: 89019 | E43: 91362 | F43: 95159 | G43: 102348 | H43: 92263 | I43: 89291 | J43: 100185 | K43: 102685
A44: Other Income | B44: 1129.98 | C44: 1452.86 | D44: 895 | E44: 1557 | F44: 1604 | G44: 1412 | H44: 1747 | I44: 1647 | J44: 1700 | K44: 1057
A45: Depreciation | B45: 6071.78 | C45: 7050.2 | D45: 6633 | E45: 6637 | F45: 6850 | G45: 7143 | H45: 6574 | I45: 6005 | J45: 5399 | K45: 5295
A46: Interest | B46: 2675.83 | C46: 2641.67 | D46: 2615 | E46: 2652 | F46: 2485 | G46: 1645 | H46: 2088 | I46: 2034 | J46: 1119 | K46: 1076
A47: Profit before tax | B47: 3202.61 | C47: 4875.39 | D47: 4864 | E47: 6035 | F47: 7687 | G47: 9309 | H47: 8870 | I47: 5767 | J47: 7605 | K47: 11504
A48: Tax | B48: 262.83 | C48: -620.65 | D48: 1563 | E48: 2203 | F48: 542 | G48: -8219 | H48: 3178 | I48: 2317 | J48: 2120 | K48: 2948
A49: Net profit | B49: 2957.71 | C49: 5407.79 | D49: 3203 | E49: 3764 | F49: 7025 | G49: 17407 | H49: 5566 | I49: 3343 | J49: 5406 | K49: 8470
A50: Operating Profit | B50: 10820.24 | C50: 13114.4 | D50: 13217 | E50: 13767 | F50: 15418 | G50: 16685 | H50: 15785 | I50: 12159 | J50: 12423 | K50: 16818
A55: BALANCE SHEET
A56: Report Date | B56: 42460 | C56: 42825 | D56: 43190 | E56: 43555 | F56: 43921 | G56: 44286 | H56: 44651 | I56: 45016 | J56: 45382 | K56: 45747
A57: Equity Share Capital | B57: 679.18 | C57: 679.22 | D57: 679.22 | E57: 679.22 | F57: 719.54 | G57: 765.81 | H57: 765.88 | I57: 766.02 | J57: 767 | K57: 736
A58: Reserves | B58: 78273.23 | C58: 57382.67 | D58: 94748.69 | E58: 59500.34 | F58: 62358.99 | G58: 54480.91 | H58: 43795.36 | I58: 44555.77 | J58: 84151 | K58: 115408
A59: Borrowings | B59: 69359.96 | C59: 78603.98 | D59: 88950.47 | E59: 106175.34 | F59: 124787.64 | G59: 142130.57 | H59: 146449.03 | I59: 134113.44 | J59: 107264 | K59: 71540
...

Sheet HistoricaIFS
B2: ="Historial Financial Statement - "&'Data Sheet'!B1 -> Historial Financial Statement - TATA MOTORS LTD
B3: Years | C3: ='Data Sheet'!B16 -> 42460 | D3: ='Data Sheet'!C16 -> 42825 | E3: ='Data Sheet'!D16 -> 43190 | F3: ='Data Sheet'!E16 -> 43555 | G3: ='Data Sheet'!F16 -> 43921 | H3: ='Data Sheet'!G16 -> 44286 | I3: ='Data Sheet'!H16 -> 44651 | J3: ='Data Sheet'!I16 -> 45016 | ... L3: ='Data Sheet'!K16 -> 45747 | M3: LTM
A4: # | B4: Income Statement
B5: Sales | C5: =IFERROR('Data Sheet'!B17,0) -> 273045.6 | D5: =IFERROR('Data Sheet'!C17,0) -> 269692.51 | E5: =IFERROR('Data Sheet'!D17,0) -> 291550.48 | F5: =IFERROR('Data Sheet'!E17,0) -> 301938.4 | G5: =IFERROR('Data Sheet'!F17,0) -> 261067.97 | H5: =IFERROR('Data Sheet'!G17,0) -> 249794.75 | I5: =IFERROR('Data Sheet'!H17,0) -> 278453.62 | J5: =IFERROR('Data Sheet'!I17,0) -> 345966.97 | ... L5: =IFERROR('Data Sheet'!K17,0) -> 439695 | M5: =IFERROR(SUM('Data Sheet'!H42:K42),0) -> 441609
B6: Sales Growth | C6: - | D6: =D5/C5-1 -> -0.01228033 | E6: =E5/D5-1 -> 0.081047746 | F6: =F5/E5-1 -> 0.035629919 | G6: =G5/F5-1 -> -0.13536016 | H6: =H5/G5-1 -> -0.043181168 | I6: =I5/H5-1 -> 0.11472967 | J6: =J5/I5-1 -> 0.24245815 | K6: =K5/J5-1 -> 0.25450126 | ... M6: =M5/L5-1 -> 0.0043530174
B8: COGS | C8: =IFERROR(SUM('Data Sheet'!B18,'Data Sheet'!B20:B22)-1*'Data Sheet'!B19,0) -> 205509.07 | D8: =IFERROR(SUM('Data Sheet'!C18,'Data Sheet'!C20:C22)-1*'Data Sheet'!C19,0) -> 205454.24 | E8: =IFERROR(SUM('Data Sheet'!D18,'Data Sheet'!D20:D22)-1*'Data Sheet'!D19,0) -> 228429.83 | F8: =IFERROR(SUM('Data Sheet'!E18,'Data Sheet'!E20:E22)-1*'Data Sheet'!E19,0) -> 242845.53 | G8: =IFERROR(SUM('Data Sheet'!F18,'Data Sheet'!F20:F22)-1*'Data Sheet'!F19,0) -> 210376.07 | H8: =IFERROR(SUM('Data Sheet'!G18,'Data Sheet'!G20:G22)-1*'Data Sheet'!G19,0) -> 195326.04 | I8: =IFERROR(SUM('Data Sheet'!H18,'Data Sheet'!H20:H22)-1*'Data Sheet'!H19,0) -> 223300.01 | J8: =IFERROR(SUM('Data Sheet'!I18,'Data Sheet'!I20:I22)-1*'Data Sheet'!I19,0) -> 274403.64 | ... L8: =IFERROR(SUM('Data Sheet'!K18,'Data Sheet'!K20:K22)-1*'Data Sheet'!K19,0) -> 340809 | M8: =IFERROR(SUM(Quarters!H5:K5),0) -> 384424
B9: Gross Margine(COGS % Sales) | C9: =C8/C5 -> 0.75265476 | D9: =D8/D5 -> 0.76180922 | E9: =E8/E5 -> 0.7835001 | F9: =F8/F5 -> 0.80428833 | G9: =G8/G5 -> 0.80582873 | H9: =H8/H5 -> 0.78194614 | I9: =I8/I5 -> 0.80192892 | J9: =J8/J5 -> 0.79314982 | ... M9: =M8/M5 -> 0.87050762
B11: Gross Profit | C11: =C5-C8 -> 67536.53 | D11: =D5-D8 -> 64238.27 | E11: =E5-E8 -> 63120.65 | F11: =F5-F8 -> 59092.87 | G11: =G5-G8 -> 50691.9 | H11: =H5-H8 -> 54468.71 | I11: =I5-I8 -> 55153.61 | J11: =J5-J8 -> 71563.33 | ... M11: =M5-M8 -> 57185
B12: Gross Profit % Sales | C12: =C11/C5 -> 0.24734524 | D12: =D11/D5 -> 0.23819078 | E12: =E11/E5 -> 0.2164999 | F12: =F11/F5 -> 0.19571167 | G12: =G11/G5 -> 0.19417127 | H12: =H11/H5 -> 0.21805386 | I12: =I11/I5 -> 0.19807108 | J12: =J11/J5 -> 0.20685018 | ... M12: =M11/M5 -> 0.12949238
B14: Selling & Gernal Expenses | C14: =IFERROR(SUM('Data Sheet'!B23:B24),0) -> 29141.28 | D14: =IFERROR(SUM('Data Sheet'!C23:C24),0) -> 34649.58 | E14: =IFERROR(SUM('Data Sheet'!D23:D24),0) -> 31662.97 | F14: =IFERROR(SUM('Data Sheet'!E23:E24),0) -> 34428.54 | G14: =IFERROR(SUM('Data Sheet'!F23:F24),0) -> 32704.83 | H14: =IFERROR(SUM('Data Sheet'!G23:G24),0) -> 22181.28 | I14: =IFERROR(SUM('Data Sheet'!H23:H24),0) -> 30433.52 | J14: =IFERROR(SUM('Data Sheet'!I23:I24),0) -> 39747.53 | ... L14: =IFERROR(SUM('Data Sheet'!K23:K24),0) -> 43670
B15: S & G Exp % Sales | C15: =C14/C5 -> 0.10672679 | D15: =D14/D5 -> 0.1284781 | E15: =E14/E5 -> 0.10860202 | F15: =F14/F5 -> 0.11402505 | G15: =G14/G5 -> 0.12527324 | H15: =H14/H5 -> 0.088798023 | I15: =I14/I5 -> 0.10929475 | J15: =J14/J5 -> 0.11488822 | ... M15: =M14/M5 -> 0
B17: EBITDA | C17: =C11-C14 -> 38395.25 | D17: =D11-D14 -> 29588.69 | E17: =E11-E14 -> 31457.68 | F17: =F11-F14 -> 24664.33 | G17: =G11-G14 -> 17987.07 | H17: =H11-H14 -> 32287.43 | I17: =I11-I14 -> 24720.09 | J17: =J11-J14 -> 31815.8 | ... M17: =M11-M14 -> 57185
B18: EBITDA % Sales | C18: =C17/C5 -> 0.14061845 | D18: =D17/D5 -> 0.10971269 | E18: =E17/E5 -> 0.10789788 | F18: =F17/F5 -> 0.081686629 | G18: =G17/G5 -> 0.068898034 | H18: =H17/H5 -> 0.12925584 | I18: =I17/I5 -> 0.088776328 | J18: =J17/J5 -> 0.091961958 | ... M18: =M17/M5 -> 0.12949238
B20: Interest | C20: 4889.08 | D20: 4238.01 | E20: 4681.79 | F20: 5758.6 | G20: 7243.33 | H20: 8097.17 | I20: 9311.86 | J20: 10225.48 | K20: 7594 | L20: 5083 | M20: =IFERROR(SUM('Data Sheet'!H46:K46),0) -> 6317
B21: Interest % Sales | C21: =C20/C5 -> 0.017905727 | D21: =D20/D5 -> 0.01571423 | E21: =E20/E5 -> 0.016058248 | F21: =F20/F5 -> 0.019072102 | G21: =G20/G5 -> 0.027744997 | H21: =H20/H5 -> 0.032415293 | I21: =I20/I5 -> 0.033441332 | J21: =J20/J5 -> 0.029556232 | ... M21: =M20/M5 -> 0.014304509
B23: Deprisiation | C23: =IFERROR('Data Sheet'!B26,0) -> 16710.78 | D23: =IFERROR('Data Sheet'!C26,0) -> 17904.99 | E23: =IFERROR('Data Sheet'!D26,0) -> 21553.59 | F23: =IFERROR('Data Sheet'!E26,0) -> 23590.63 | G23: =IFERROR('Data Sheet'!F26,0) -> 21425.43 | H23: =IFERROR('Data Sheet'!G26,0) -> 23546.71 | I23: =IFERROR('Data Sheet'!H26,0) -> 24835.69 | J23: =IFERROR('Data Sheet'!I26,0) -> 24860.36 | ... L23: =IFERROR('Data Sheet'!K26,0) -> 23256 | M23: =IFERROR(SUM('Data Sheet'!H45:K45),0) -> 23273
B24: Deprisiation % Sales | C24: =C23/C5 -> 0.061201426 | D24: =D23/D5 -> 0.066390387 | E24: =E23/E5 -> 0.073927472 | F24: =F23/F5 -> 0.078130605 | G24: =G23/G5 -> 0.082068398 | H24: =H23/H5 -> 0.094264231 | I24: =I23/I5 -> 0.089191478 | J24: =J23/J5 -> 0.071857611 | ... M24: =M23/M5 -> 0.052700466
B26: EBT | C26: =IFERROR(C17-SUM(C20,C23),0) -> 16795.39 | D26: =IFERROR(D17-SUM(D20,D23),0) -> 7445.69 | E26: =IFERROR(E17-SUM(E20,E23),0) -> 5222.3 | F26: =IFERROR(F17-SUM(F20,F23),0) -> -4684.9 | G26: =IFERROR(G17-SUM(G20,G23),0) -> -10681.69 | H26: =IFERROR(H17-SUM(H20,H23),0) -> 643.55 | I26: =IFERROR(I17-SUM(I20,I23),0) -> -9427.46 | J26: =IFERROR(J17-SUM(J20,J23),0) -> -3270.04 | ... M26: =IFERROR(M17-SUM(M20,M23),0) -> 27595 | O26: =L26-K26-1 -> 3885
B27: EBT % Sales | C27: =C26/C5 -> 0.061511301 | D27: =D26/D5 -> 0.027608071 | E27: =E26/E5 -> 0.017912164 | F27: =F26/F5 -> -0.015516079 | G27: =G26/G5 -> -0.04091536 | H27: =H26/H5 -> 0.0025763152 | I27: =I26/I5 -> -0.033856482 | J27: =J26/J5 -> -0.009451885 | ... M27: =M26/M5 -> 0.062487404
B29: TAX | C29: =IFERROR('Data Sheet'!B48,0) -> 262.83 | D29: =IFERROR('Data Sheet'!C48,0) -> -620.65 | E29: =IFERROR('Data Sheet'!D48,0) -> 1563 | F29: =IFERROR('Data Sheet'!E48,0) -> 2203 | G29: =IFERROR('Data Sheet'!F48,0) -> 542 | H29: =IFERROR('Data Sheet'!G48,0) -> -8219 | I29: =IFERROR('Data Sheet'!H48,0) -> 3178 | J29: =IFERROR('Data Sheet'!I48,0) -> 2317 | ... L29: =IFERROR('Data Sheet'!K48,0) -> 2948 | M29: =IFERROR(SUM('Data Sheet'!H48:K48),0) -> 10563
B30: TAX % Sales | C30: =C29/C5 -> 0.00096258647 | D30: =D29/D5 -> -0.0023013246 | E30: =E29/E5 -> 0.0053609927 | F30: =F29/F5 -> 0.0072961902 | G30: =G29/G5 -> 0.0020760877 | H30: =H29/H5 -> -0.032903013 | I30: =I29/I5 -> 0.011413032 | J30: =J29/J5 -> 0.0066971711 | ... M30: =M29/M5 -> 0.023919349
B32: Net Profit | C32: ='Data Sheet'!B49 -> 2957.71 | D32: ='Data Sheet'!C49 -> 5407.79 | E32: ='Data Sheet'!D49 -> 3203 | F32: ='Data Sheet'!E49 -> 3764 | G32: ='Data Sheet'!F49 -> 7025 | H32: ='Data Sheet'!G49 -> 17407 | I32: ='Data Sheet'!H49 -> 5566 | J32: ='Data Sheet'!I49 -> 3343 | ... L32: ='Data Sheet'!K49 -> 8470 | M32: =IFERROR(SUM('Data Sheet'!H49:K49),0) -> 22785
B33: Net Profit % Sales | C33: =IFERROR(C32/C5,0) -> 0.010832293 | D33: =IFERROR(D32/D5,0) -> 0.020051688 | E33: =IFERROR(E32/E5,0) -> 0.010986091 | F33: =IFERROR(F32/F5,0) -> 0.012466119 | G33: =IFERROR(G32/G5,0) -> 0.026908701 | H33: =IFERROR(H32/H5,0) -> 0.069685212 | I33: =IFERROR(I32/I5,0) -> 0.019988966 | J33: =IFERROR(J32/J5,0) -> 0.0096627721 | ... M33: =IFERROR(M32/M5,0) -> 0.051595416
B35: No Of Equity Share | C35: =IFERROR('Data Sheet'!B93,0) -> 288.72 | D35: =IFERROR('Data Sheet'!C93,0) -> 288.73 | E35: =IFERROR('Data Sheet'!D93,0) -> 288.73 | F35: =IFERROR('Data Sheet'!E93,0) -> 288.73 | G35: =IFERROR('Data Sheet'!F93,0) -> 308.9 | H35: =IFERROR('Data Sheet'!G93,0) -> 332.03 | I35: =IFERROR('Data Sheet'!H93,0) -> 332.07 | J35: =IFERROR('Data Sheet'!I93,0) -> 332.13 | ... L35: =IFERROR('Data Sheet'!K93,0) -> 368.13
B37: EPS | C37: =IFERROR(C32/C35,0) -> 10.244216 | D37: =IFERROR(D32/D35,0) -> 18.729574 | E37: =IFERROR(E32/E35,0) -> 11.093409 | F37: =IFERROR(F32/F35,0) -> 13.036401 | G37: =IFERROR(G32/G35,0) -> 22.741988 | H37: =IFERROR(H32/H35,0) -> 52.425986 | I37: =IFERROR(I32/I35,0) -> 16.761526 | J37: =IFERROR(J32/J35,0) -> 10.065336 | ... M37: =IFERROR(M32/M35,0) -> 0
B38: EPS Growth % | D38: =IFERROR(D37/C37-1,0) -> 0.82830727 | E38: =IFERROR(E37/D37-1,0) -> -0.40770629 | F38: =IFERROR(F37/E37-1,0) -> 0.1751483 | G38: =IFERROR(G37/F37-1,0) -> 0.74449897 | H38: =IFERROR(H37/G37-1,0) -> 1.3052508 | I38: =IFERROR(I37/H37-1,0) -> -0.6802821 | J38: =IFERROR(J37/I37-1,0) -> -0.39949765 | K38: =IFERROR(K37/J37-1,0) -> 0.61594269 | ... M38: =IFERROR(M37/L37-1,0) -> -1
B40: Dividend per Share | C40: =IFERROR('Data Sheet'!B31/HistoricaIFS!C35,0) -> 0.23524522 | D40: =IFERROR('Data Sheet'!C31/HistoricaIFS!D35,0) -> 0 | E40: =IFERROR('Data Sheet'!D31/HistoricaIFS!E35,0) -> 0 | F40: =IFERROR('Data Sheet'!E31/HistoricaIFS!F35,0) -> 0 | G40: =IFERROR('Data Sheet'!F31/HistoricaIFS!G35,0) -> 0 | H40: =IFERROR('Data Sheet'!G31/HistoricaIFS!H35,0) -> 0 | I40: =IFERROR('Data Sheet'!H31/HistoricaIFS!I35,0) -> 0 | J40: =IFERROR('Data Sheet'!I31/HistoricaIFS!J35,0) -> 2.3063861 | ... M40: =IFERROR('Data Sheet'!L31/HistoricaIFS!M35,0) -> 0
B41: Dividend Payout Ratio | C41: =C40/C37 -> 0.022963712 | D41: =D40/D37 -> 0 | E41: =E40/E37 -> 0 | F41: =F40/F37 -> 0 | G41: =G40/G37 -> 0 | H41: =H40/H37 -> 0 | I41: =I40/I37 -> 0 | J41: =J40/J37 -> 0.22914149 | ... M41: =M40/M37 -> #DIV/0!
B43: Retained Earning | C43: =IFERROR(IF(C37>C40,1-C40,0),0) -> 0.76475478 | D43: =IFERROR(IF(D37>D40,1-D40,0),0) -> 1 | E43: =IFERROR(IF(E37>E40,1-E40,0),0) -> 1 | F43: =IFERROR(IF(F37>F40,1-F40,0),0) -> 1 | G43: =IFERROR(IF(G37>G40,1-G40,0),0) -> 1 | H43: =IFERROR(IF(H37>H40,1-H40,0),0) -> 1 | I43: =IFERROR(IF(I37>I40,1-I40,0),0) -> 1 | J43: =IFERROR(IF(J37>J40,1-J40,0),0) -> -1.3063861 | ... M43: =IFERROR(IF(M37>M40,1-M40,0),0) -> 0
B46: Balance Sheet
B47: Equity Share Capital | C47: =IFERROR('Data Sheet'!B57,0) -> 679.18 | D47: =IFERROR('Data Sheet'!C57,0) -> 679.22 | E47: =IFERROR('Data Sheet'!D57,0) -> 679.22 | F47: =IFERROR('Data Sheet'!E57,0) -> 679.22 | G47: =IFERROR('Data Sheet'!F57,0) -> 719.54 | H47: =IFERROR('Data Sheet'!G57,0) -> 765.81 | I47: =IFERROR('Data Sheet'!H57,0) -> 765.88 | J47: =IFERROR('Data Sheet'!I57,0) -> 766.02 | ... L47: =IFERROR('Data Sheet'!K57,0) -> 736
B48: Reserves | C48: =IFERROR('Data Sheet'!B58,0) -> 78273.23 | D48: =IFERROR('Data Sheet'!C58,0) -> 57382.67 | E48: =IFERROR('Data Sheet'!D58,0) -> 94748.69 | F48: =IFERROR('Data Sheet'!E58,0) -> 59500.34 | G48: =IFERROR('Data Sheet'!F58,0) -> 62358.99 | H48: =IFERROR('Data Sheet'!G58,0) -> 54480.91 | I48: =IFERROR('Data Sheet'!H58,0) -> 43795.36 | J48: =IFERROR('Data Sheet'!I58,0) -> 44555.77 | ... L48: =IFERROR('Data Sheet'!K58,0) -> 115408
B49: Borrowings | C49: =IFERROR('Data Sheet'!B59,0) -> 69359.96 | D49: =IFERROR('Data Sheet'!C59,0) -> 78603.98 | E49: =IFERROR('Data Sheet'!D59,0) -> 88950.47 | F49: =IFERROR('Data Sheet'!E59,0) -> 106175.34 | G49: =IFERROR('Data Sheet'!F59,0) -> 124787.64 | H49: =IFERROR('Data Sheet'!G59,0) -> 142130.57 | I49: =IFERROR('Data Sheet'!H59,0) -> 146449.03 | J49: =IFERROR('Data Sheet'!I59,0) -> 134113.44 | ... L49: =IFERROR('Data Sheet'!K59,0) -> 71540
B50: Other Liabilities | C50: =IFERROR('Data Sheet'!B60,0) -> 114871.75 | D50: =IFERROR('Data Sheet'!C60,0) -> 135914.49 | E50: =IFERROR('Data Sheet'!D60,0) -> 142813.43 | F50: =IFERROR('Data Sheet'!E60,0) -> 139348.59 | G50: =IFERROR('Data Sheet'!F60,0) -> 132313.22 | H50: =IFERROR('Data Sheet'!G60,0) -> 144192.62 | I50: =IFERROR('Data Sheet'!H60,0) -> 138051.22 | J50: =IFERROR('Data Sheet'!I60,0) -> 155239.2 | ... L50: =IFERROR('Data Sheet'!K60,0) -> 189289
B51: Total Liablities | C51: =IFERROR('Data Sheet'!B61,0) -> 263184.12 | D51: =IFERROR('Data Sheet'!C61,0) -> 272580.36 | E51: =IFERROR('Data Sheet'!D61,0) -> 327191.81 | F51: =IFERROR('Data Sheet'!E61,0) -> 305703.49 | G51: =IFERROR('Data Sheet'!F61,0) -> 320179.39 | H51: =IFERROR('Data Sheet'!G61,0) -> 341569.91 | I51: =IFERROR('Data Sheet'!H61,0) -> 329061.49 | J51: =IFERROR('Data Sheet'!I61,0) -> 334674.43 | ... L51: =IFERROR('Data Sheet'!K61,0) -> 376973
B54: Fix Asset Net Block | C54: =IFERROR('Data Sheet'!B62,0) -> 107231.76 | D54: =IFERROR('Data Sheet'!C62,0) -> 95944.08 | E54: =IFERROR('Data Sheet'!D62,0) -> 121413.86 | F54: =IFERROR('Data Sheet'!E62,0) -> 111234.47 | G54: =IFERROR('Data Sheet'!F62,0) -> 127107.14 | H54: =IFERROR('Data Sheet'!G62,0) -> 138707.61 | I54: =IFERROR('Data Sheet'!H62,0) -> 138855.45 | J54: =IFERROR('Data Sheet'!I62,0) -> 132079.76 | ... L54: =IFERROR('Data Sheet'!K62,0) -> 115697
B55: Capital Work in Progress | C55: =IFERROR('Data Sheet'!B63,0) -> 25918.94 | D55: =IFERROR('Data Sheet'!C63,0) -> 33698.84 | E55: =IFERROR('Data Sheet'!D63,0) -> 40033.5 | F55: =IFERROR('Data Sheet'!E63,0) -> 31883.84 | G55: =IFERROR('Data Sheet'!F63,0) -> 35622.29 | H55: =IFERROR('Data Sheet'!G63,0) -> 20963.93 | I55: =IFERROR('Data Sheet'!H63,0) -> 10251.09 | J55: =IFERROR('Data Sheet'!I63,0) -> 14274.5 | ... L55: =IFERROR('Data Sheet'!K63,0) -> 65806
B56: Investments | C56: =IFERROR('Data Sheet'!B64,0) -> 23767.02 | D56: =IFERROR('Data Sheet'!C64,0) -> 20337.92 | E56: =IFERROR('Data Sheet'!D64,0) -> 20812.75 | F56: =IFERROR('Data Sheet'!E64,0) -> 15770.72 | G56: =IFERROR('Data Sheet'!F64,0) -> 16308.48 | H56: =IFERROR('Data Sheet'!G64,0) -> 24620.28 | I56: =IFERROR('Data Sheet'!H64,0) -> 29379.53 | J56: =IFERROR('Data Sheet'!I64,0) -> 26379.16 | ... L56: =IFERROR('Data Sheet'!K64,0) -> 35656
B57: Other Assets | C57: =IFERROR('Data Sheet'!B65-SUM('Data Sheet'!B67:B69),0) -> 29579.36 | D57: =IFERROR('Data Sheet'!C65-SUM('Data Sheet'!C67:C69),0) -> 37360.78 | E57: =IFERROR('Data Sheet'!D65-SUM('Data Sheet'!D67:D69),0) -> 48286.86 | F57: =IFERROR('Data Sheet'!E65-SUM('Data Sheet'!E67:E69),0) -> 56155.74 | G57: =IFERROR('Data Sheet'!F65-SUM('Data Sheet'!F67:F69),0) -> 58784.94 | H57: =IFERROR('Data Sheet'!G65-SUM('Data Sheet'!G67:G69),0) -> 61717.96 | I57: =IFERROR('Data Sheet'!H65-SUM('Data Sheet'!H67:H69),0) -> 62223.77 | J57: =IFERROR('Data Sheet'!I65-SUM('Data Sheet'!I67:I69),0) -> 68432.09 | ... L57: =IFERROR('Data Sheet'!K65-SUM('Data Sheet'!K67:K69),0) -> 58463
B58: Total Non Current Asset | C58: =SUM(C54:C57) -> 186497.08 | D58: =SUM(D54:D57) -> 187341.62 | E58: =SUM(E54:E57) -> 230546.97 | F58: =SUM(F54:F57) -> 215044.77 | G58: =SUM(G54:G57) -> 237822.85 | H58: =SUM(H54:H57) -> 246009.78 | I58: =SUM(I54:I57) -> 240709.84 | J58: =SUM(J54:J57) -> 241165.51 | ... L58: =SUM(L54:L57) -> 275622
...

Sheet Common Size Statement
B2: ="Common Size"&" "&"-"&'Data Sheet'!B1 -> Common Size -TATA MOTORS LTD
B4: Particular | C4: ='Data Sheet'!B56 -> 42460 | D4: ='Data Sheet'!C56 -> 42825 | E4: ='Data Sheet'!D56 -> 43190 | F4: ='Data Sheet'!E56 -> 43555 | G4: ='Data Sheet'!F56 -> 43921 | H4: ='Data Sheet'!G56 -> 44286 | I4: ='Data Sheet'!H56 -> 44651 | J4: ='Data Sheet'!I56 -> 45016 | ... L4: ='Data Sheet'!K56 -> 45747
B5: ='Data Sheet'!A17 -> Sales | C5: ='Data Sheet'!B17/'Data Sheet'!B$17 -> 1 | D5: ='Data Sheet'!C17/'Data Sheet'!C$17 -> 1 | E5: ='Data Sheet'!D17/'Data Sheet'!D$17 -> 1 | F5: ='Data Sheet'!E17/'Data Sheet'!E$17 -> 1 | G5: ='Data Sheet'!F17/'Data Sheet'!F$17 -> 1 | H5: ='Data Sheet'!G17/'Data Sheet'!G$17 -> 1 | I5: ='Data Sheet'!H17/'Data Sheet'!H$17 -> 1 | J5: ='Data Sheet'!I17/'Data Sheet'!I$17 -> 1 | ... L5: ='Data Sheet'!K17/'Data Sheet'!K$17 -> 1
B6: ='Data Sheet'!A18 -> Raw Material Cost | C6: ='Data Sheet'!B18/'Data Sheet'!B$17 -> 0.60844786 | D6: ='Data Sheet'!C18/'Data Sheet'!C$17 -> 0.64256171 | E6: ='Data Sheet'!D18/'Data Sheet'!D$17 -> 0.64447357 | F6: ='Data Sheet'!E18/'Data Sheet'!E$17 -> 0.64340246 | G6: ='Data Sheet'!F18/'Data Sheet'!F$17 -> 0.63163559 | H6: ='Data Sheet'!G18/'Data Sheet'!G$17 -> 0.6149343 | I6: ='Data Sheet'!H18/'Data Sheet'!H$17 -> 0.64389657 | J6: ='Data Sheet'!I18/'Data Sheet'!I$17 -> 0.66842005 | ... L6: ='Data Sheet'!K18/'Data Sheet'!K$17 -> 0.611674
B7: ='Data Sheet'!A19 -> Change in Inventory | C7: ='Data Sheet'!B19/'Data Sheet'!B$17 -> 0.010075204 | D7: ='Data Sheet'!C19/'Data Sheet'!C$17 -> 0.027438359 | E7: ='Data Sheet'!D19/'Data Sheet'!D$17 -> 0.007019642 | F7: ='Data Sheet'!E19/'Data Sheet'!E$17 -> -0.0068003275 | G7: ='Data Sheet'!F19/'Data Sheet'!F$17 -> -0.008546395 | H7: ='Data Sheet'!G19/'Data Sheet'!G$17 -> -0.018752035 | I7: ='Data Sheet'!H19/'Data Sheet'!H$17 -> -0.0057118668 | J7: ='Data Sheet'!I19/'Data Sheet'!I$17 -> 0.01382103 | ... L7: ='Data Sheet'!K19/'Data Sheet'!K$17 -> -0.0064499255
B8: ='Data Sheet'!A20 -> Power and Fuel | C8: ='Data Sheet'!B20/'Data Sheet'!B$17 -> 0.0041884213 | D8: ='Data Sheet'!C20/'Data Sheet'!C$17 -> 0.0043005273 | E8: ='Data Sheet'!D20/'Data Sheet'!D$17 -> 0.004486633 | F8: ='Data Sheet'!E20/'Data Sheet'!E$17 -> 0.0052524952 | G8: ='Data Sheet'!F20/'Data Sheet'!F$17 -> 0.0048452899 | H8: ='Data Sheet'!G20/'Data Sheet'!G$17 -> 0.0044551377 | I8: ='Data Sheet'!H20/'Data Sheet'!H$17 -> 0.0078228109 | J8: ='Data Sheet'!I20/'Data Sheet'!I$17 -> 0.007264653 | ... L8: ='Data Sheet'!K20/'Data Sheet'!K$17 -> 0.0055561241
B9: ='Data Sheet'!A21 -> Other Mfr. Exp | C9: ='Data Sheet'!B21/'Data Sheet'!B$17 -> 0.044320546 | D9: ='Data Sheet'!C21/'Data Sheet'!C$17 -> 0.037329068 | E9: ='Data Sheet'!D21/'Data Sheet'!D$17 -> 0.037632111 | F9: ='Data Sheet'!E21/'Data Sheet'!E$17 -> 0.038731543 | G9: ='Data Sheet'!F21/'Data Sheet'!F$17 -> 0.044208832 | H9: ='Data Sheet'!G21/'Data Sheet'!G$17 -> 0.033119871 | I9: ='Data Sheet'!H21/'Data Sheet'!H$17 -> 0.033856195 | J9: ='Data Sheet'!I21/'Data Sheet'!I$17 -> 0.03400894 | ... L9: ='Data Sheet'!K21/'Data Sheet'!K$17 -> 0.042786477
B10: ='Data Sheet'!A22 -> Employee Cost | C10: ='Data Sheet'!B22/'Data Sheet'!B$17 -> 0.10577314 | D10: ='Data Sheet'!C22/'Data Sheet'!C$17 -> 0.10505627 | E10: ='Data Sheet'!D22/'Data Sheet'!D$17 -> 0.10392742 | F10: ='Data Sheet'!E22/'Data Sheet'!E$17 -> 0.1101015 | G10: ='Data Sheet'!F22/'Data Sheet'!F$17 -> 0.11659263 | H10: ='Data Sheet'!G22/'Data Sheet'!G$17 -> 0.11068479 | I10: ='Data Sheet'!H22/'Data Sheet'!H$17 -> 0.11064148 | J10: ='Data Sheet'!I22/'Data Sheet'!I$17 -> 0.097277205 | ... L10: ='Data Sheet'!K22/'Data Sheet'!K$17 -> 0.10863667
B11: ='Data Sheet'!A23 -> Selling and admin | C11: ='Data Sheet'!B23/'Data Sheet'!B$17 -> 0.080542957 | D11: ='Data Sheet'!C23/'Data Sheet'!C$17 -> 0.11138381 | E11: ='Data Sheet'!D23/'Data Sheet'!D$17 -> 0.10634378 | F11: ='Data Sheet'!E23/'Data Sheet'!E$17 -> 0.10836581 | G11: ='Data Sheet'!F23/'Data Sheet'!F$17 -> 0.11203335 | H11: ='Data Sheet'!G23/'Data Sheet'!G$17 -> 0.092138806 | I11: ='Data Sheet'!H23/'Data Sheet'!H$17 -> 0.10488425 | J11: ='Data Sheet'!I23/'Data Sheet'!I$17 -> 0.10070091 | ... L11: ='Data Sheet'!K23/'Data Sheet'!K$17 -> 0.10711743
B12: ='Data Sheet'!A24 -> Other Expenses | C12: ='Data Sheet'!B24/'Data Sheet'!B$17 -> 0.026183832 | D12: ='Data Sheet'!C24/'Data Sheet'!C$17 -> 0.017094283 | E12: ='Data Sheet'!D24/'Data Sheet'!D$17 -> 0.0022582367 | F12: ='Data Sheet'!E24/'Data Sheet'!E$17 -> 0.0056592338 | G12: ='Data Sheet'!F24/'Data Sheet'!F$17 -> 0.013239885 | H12: ='Data Sheet'!G24/'Data Sheet'!G$17 -> -0.0033407828 | I12: ='Data Sheet'!H24/'Data Sheet'!H$17 -> 0.0044105011 | J12: ='Data Sheet'!I24/'Data Sheet'!I$17 -> 0.014187308 | ... L12: ='Data Sheet'!K24/'Data Sheet'!K$17 -> -0.0077985877
B13: ='Data Sheet'!A25 -> Other Income | C13: ='Data Sheet'!B25/'Data Sheet'!B$17 -> -0.0097771947 | D13: ='Data Sheet'!C25/'Data Sheet'!C$17 -> 0.0069304854 | E13: ='Data Sheet'!D25/'Data Sheet'!D$17 -> 0.020348895 | F13: ='Data Sheet'!E25/'Data Sheet'!E$17 -> -0.088383094 | G13: ='Data Sheet'!F25/'Data Sheet'!F$17 -> 0.00038959203 | H13: ='Data Sheet'!G25/'Data Sheet'!G$17 -> -0.044507861 | I13: ='Data Sheet'!H25/'Data Sheet'!H$17 -> 0.0087053995 | J13: ='Data Sheet'!I25/'Data Sheet'!I$17 -> 0.019261868 | ... L13: ='Data Sheet'!K25/'Data Sheet'!K$17 -> 0.026777653
B14: ='Data Sheet'!A26 -> Depreciation | C14: ='Data Sheet'!B26/'Data Sheet'!B$17 -> 0.061201426 | D14: ='Data Sheet'!C26/'Data Sheet'!C$17 -> 0.066390387 | E14: ='Data Sheet'!D26/'Data Sheet'!D$17 -> 0.073927472 | F14: ='Data Sheet'!E26/'Data Sheet'!E$17 -> 0.078130605 | G14: ='Data Sheet'!F26/'Data Sheet'!F$17 -> 0.082068398 | H14: ='Data Sheet'!G26/'Data Sheet'!G$17 -> 0.094264231 | I14: ='Data Sheet'!H26/'Data Sheet'!H$17 -> 0.089191478 | J14: ='Data Sheet'!I26/'Data Sheet'!I$17 -> 0.071857611 | ... L14: ='Data Sheet'!K26/'Data Sheet'!K$17 -> 0.052891209
B15: ='Data Sheet'!A27 -> Interest | C15: ='Data Sheet'!B27/'Data Sheet'!B$17 -> 0.017905727 | D15: ='Data Sheet'!C27/'Data Sheet'!C$17 -> 0.01571423 | E15: ='Data Sheet'!D27/'Data Sheet'!D$17 -> 0.016058248 | F15: ='Data Sheet'!E27/'Data Sheet'!E$17 -> 0.019072102 | G15: ='Data Sheet'!F27/'Data Sheet'!F$17 -> 0.027744997 | H15: ='Data Sheet'!G27/'Data Sheet'!G$17 -> 0.032415293 | I15: ='Data Sheet'!H27/'Data Sheet'!H$17 -> 0.033441332 | J15: ='Data Sheet'!I27/'Data Sheet'!I$17 -> 0.029556232 | ... L15: ='Data Sheet'!K27/'Data Sheet'!K$17 -> 0.011560286
B16: ='Data Sheet'!A28 -> Profit before tax | C16: ='Data Sheet'!B28/'Data Sheet'!B$17 -> 0.051734106 | D16: ='Data Sheet'!C28/'Data Sheet'!C$17 -> 0.034538557 | E16: ='Data Sheet'!D28/'Data Sheet'!D$17 -> 0.038261059 | F16: ='Data Sheet'!E28/'Data Sheet'!E$17 -> -0.10389917 | G16: ='Data Sheet'!F28/'Data Sheet'!F$17 -> -0.040525768 | H16: ='Data Sheet'!G28/'Data Sheet'!G$17 -> -0.041931546 | I16: ='Data Sheet'!H28/'Data Sheet'!H$17 -> -0.025151083 | J16: ='Data Sheet'!I28/'Data Sheet'!I$17 -> 0.0098099827 | ... L16: ='Data Sheet'!K28/'Data Sheet'!K$17 -> 0.087904115
... B20: ='Data Sheet'!A32 -> EBITDA | C20: ='Data Sheet'!B32/'Data Sheet'!B$17 -> 0.13259404 | D20: ='Data Sheet'!C32/'Data Sheet'!C$17 -> 0.12180016 | E20: ='Data Sheet'!D32/'Data Sheet'!D$17 -> 0.13570967 | F20: ='Data Sheet'!E32/'Data Sheet'!E$17 -> -0.0063405317 | G20: ='Data Sheet'!F32/'Data Sheet'!F$17 -> 0.065090942 | H20: ='Data Sheet'!G32/'Data Sheet'!G$17 -> 0.083005548 | I20: ='Data Sheet'!H32/'Data Sheet'!H$17 -> 0.096739163 | J20: ='Data Sheet'!I32/'Data Sheet'!I$17 -> 0.11042728 | ... L20: ='Data Sheet'!K32/'Data Sheet'!K$17 -> 0.15163011
B22: ="Common Size Statement Balance Sheet"&" "&"-"&'Data Sheet'!B1 -> Common Size Statement Balance Sheet -TATA MOTORS LTD
B24: Particular | C24: ='Data Sheet'!B56 -> 42460 | D24: ='Data Sheet'!C56 -> 42825 | E24: ='Data Sheet'!D56 -> 43190 | F24: ='Data Sheet'!E56 -> 43555 | G24: ='Data Sheet'!F56 -> 43921 | H24: ='Data Sheet'!G56 -> 44286 | I24: ='Data Sheet'!H56 -> 44651 | J24: ='Data Sheet'!I56 -> 45016 | ... L24: ='Data Sheet'!K56 -> 45747
B25: ='Data Sheet'!A57 -> Equity Share Capital | C25: ='Data Sheet'!B57/'Data Sheet'!B$61 -> 0.0025806268 | D25: ='Data Sheet'!C57/'Data Sheet'!C$61 -> 0.0024918156 | E25: ='Data Sheet'!D57/'Data Sheet'!D$61 -> 0.0020759077 | F25: ='Data Sheet'!E57/'Data Sheet'!E$61 -> 0.0022218261 | G25: ='Data Sheet'!F57/'Data Sheet'!F$61 -> 0.0022473027 | H25: ='Data Sheet'!G57/'Data Sheet'!G$61 -> 0.00224203 | I25: ='Data Sheet'!H57/'Data Sheet'!H$61 -> 0.0023274677 | J25: ='Data Sheet'!I57/'Data Sheet'!I$61 -> 0.0022888513 | ... L25: ='Data Sheet'!K57/'Data Sheet'!K$61 -> 0.0019523945
B26: ='Data Sheet'!A58 -> Reserves | C26: ='Data Sheet'!B58/'Data Sheet'!B$61 -> 0.29740864 | D26: ='Data Sheet'!C58/'Data Sheet'!C$61 -> 0.21051652 | E26: ='Data Sheet'!D58/'Data Sheet'!D$61 -> 0.28958148 | F26: ='Data Sheet'!E58/'Data Sheet'!E$61 -> 0.19463415 | G26: ='Data Sheet'!F58/'Data Sheet'!F$61 -> 0.19476266 | H26: ='Data Sheet'!G58/'Data Sheet'!G$61 -> 0.15950149 | I26: ='Data Sheet'!H58/'Data Sheet'!H$61 -> 0.13309172 | J26: ='Data Sheet'!I58/'Data Sheet'!I$61 -> 0.13313168 | ... L26: ='Data Sheet'!K58/'Data Sheet'!K$61 -> 0.30614394
B27: ='Data Sheet'!A59 -> Borrowings | C27: ='Data Sheet'!B59/'Data Sheet'!B$61 -> 0.26354158 | D27: ='Data Sheet'!C59/'Data Sheet'!C$61 -> 0.28836993 | E27: ='Data Sheet'!D59/'Data Sheet'!D$61 -> 0.27186032 | F27: ='Data Sheet'!E59/'Data Sheet'!E$61 -> 0.34731478 | G27: ='Data Sheet'!F59/'Data Sheet'!F$61 -> 0.38974289 | H27: ='Data Sheet'!G59/'Data Sheet'!G$61 -> 0.41610975 | I27: ='Data Sheet'!H59/'Data Sheet'!H$61 -> 0.44505065 | J27: ='Data Sheet'!I59/'Data Sheet'!I$61 -> 0.40072807 | ... L27: ='Data Sheet'!K59/'Data Sheet'!K$61 -> 0.18977486
B28: ='Data Sheet'!A60 -> Other Liabilities | C28: ='Data Sheet'!B60/'Data Sheet'!B$61 -> 0.43646915 | D28: ='Data Sheet'!C60/'Data Sheet'!C$61 -> 0.49862173 | E28: ='Data Sheet'!D60/'Data Sheet'!D$61 -> 0.43648229 | F28: ='Data Sheet'!E60/'Data Sheet'!E$61 -> 0.45582924 | G28: ='Data Sheet'!F60/'Data Sheet'!F$61 -> 0.41324715 | H28: ='Data Sheet'!G60/'Data Sheet'!G$61 -> 0.42214673 | I28: ='Data Sheet'!H60/'Data Sheet'!H$61 -> 0.41953016 | J28: ='Data Sheet'!I60/'Data Sheet'!I$61 -> 0.46385139 | ... L28: ='Data Sheet'!K60/'Data Sheet'!K$61 -> 0.5021288
B29: ='Data Sheet'!A61 -> Total | C29: ='Data Sheet'!B61/'Data Sheet'!B$61 -> 1 | D29: ='Data Sheet'!C61/'Data Sheet'!C$61 -> 1 | E29: ='Data Sheet'!D61/'Data Sheet'!D$61 -> 1 | F29: ='Data Sheet'!E61/'Data Sheet'!E$61 -> 1 | G29: ='Data Sheet'!F61/'Data Sheet'!F$61 -> 1 | H29: ='Data Sheet'!G61/'Data Sheet'!G$61 -> 1 | I29: ='Data Sheet'!H61/'Data Sheet'!H$61 -> 1 | J29: ='Data Sheet'!I61/'Data Sheet'!I$61 -> 1 | ... L29: ='Data Sheet'!K61/'Data Sheet'!K$61 -> 1
B31: ='Data Sheet'!A62 -> Net Block | C31: ='Data Sheet'!B62/'Data Sheet'!B$75 -> 0.40744008 | D31: ='Data Sheet'!C62/'Data Sheet'!C$75 -> 0.35198457 | E31: ='Data Sheet'!D62/'Data Sheet'!D$75 -> 0.37107854 | F31: ='Data Sheet'!E62/'Data Sheet'!E$75 -> 0.36386392 | G31: ='Data Sheet'!F62/'Data Sheet'!F$75 -> 0.39698726 | H31: ='Data Sheet'!G62/'Data Sheet'!G$75 -> 0.40608849 | I31: ='Data Sheet'!H62/'Data Sheet'!H$75 -> 0.42197417 | J31: ='Data Sheet'!I62/'Data Sheet'!I$75 -> 0.39465148 | ... L31: ='Data Sheet'!K62/'Data Sheet'!K$75 -> 0.30691057
B32: ='Data Sheet'!A63 -> Capital Work in Progress | C32: ='Data Sheet'!B63/'Data Sheet'!B$75 -> 0.098482158 | D32: ='Data Sheet'!C63/'Data Sheet'!C$75 -> 0.12362901 | E32: ='Data Sheet'!D63/'Data Sheet'!D$75 -> 0.12235484 | F32: ='Data Sheet'!E63/'Data Sheet'!E$75 -> 0.10429662 | G32: ='Data Sheet'!F63/'Data Sheet'!F$75 -> 0.11125729 | H32: ='Data Sheet'!G63/'Data Sheet'!G$75 -> 0.061375225 | I32: ='Data Sheet'!H63/'Data Sheet'!H$75 -> 0.031152506 | J32: ='Data Sheet'!I63/'Data Sheet'!I$75 -> 0.042651899 | ... L32: ='Data Sheet'!K63/'Data Sheet'!K$75 -> 0.17456423
B33: ='Data Sheet'!A64 -> Investments | C33: ='Data Sheet'!B64/'Data Sheet'!B$75 -> 0.090305676 | D33: ='Data Sheet'!C64/'Data Sheet'!C$75 -> 0.074612566 | E33: ='Data Sheet'!D64/'Data Sheet'!D$75 -> 0.063610241 | F33: ='Data Sheet'!E64/'Data Sheet'!E$75 -> 0.051588289 | G33: ='Data Sheet'!F64/'Data Sheet'!F$75 -> 0.050935446 | H33: ='Data Sheet'!G64/'Data Sheet'!G$75 -> 0.072079768 | I33: ='Data Sheet'!H64/'Data Sheet'!H$75 -> 0.089282796 | J33: ='Data Sheet'!I64/'Data Sheet'!I$75 -> 0.078820363 | ... L33: ='Data Sheet'!K64/'Data Sheet'!K$75 -> 0.094585023
B34: ='Data Sheet'!A65 -> Other Assets | C34: ='Data Sheet'!B65/'Data Sheet'!B$75 -> 0.40377208 | D34: ='Data Sheet'!C65/'Data Sheet'!C$75 -> 0.44977386 | E34: ='Data Sheet'!D65/'Data Sheet'!D$75 -> 0.44295638 | F34: ='Data Sheet'!E65/'Data Sheet'!E$75 -> 0.48025117 | G34: ='Data Sheet'!F65/'Data Sheet'!F$75 -> 0.44082 | H34: ='Data Sheet'!G65/'Data Sheet'!G$75 -> 0.46045651 | I34: ='Data Sheet'!H65/'Data Sheet'!H$75 -> 0.45759053 | J34: ='Data Sheet'!I65/'Data Sheet'!I$75 -> 0.48387626 | ... L34: ='Data Sheet'!K65/'Data Sheet'!K$75 -> 0.42394018
B35: ='Data Sheet'!A67 -> Receivables | C35: ='Data Sheet'!B67/'Data Sheet'!B$75 -> 0.051564319 | D35: ='Data Sheet'!C67/'Data Sheet'!C$75 -> 0.051638166 | E35: ='Data Sheet'!D67/'Data Sheet'!D$75 -> 0.060800116 | F35: ='Data Sheet'!E67/'Data Sheet'!E$75 -> 0.062139199 | G35: ='Data Sheet'!F67/'Data Sheet'!F$75 -> 0.034895094 | H35: ='Data Sheet'!G67/'Data Sheet'!G$75 -> 0.037120014 | I35: ='Data Sheet'!H67/'Data Sheet'!H$75 -> 0.037810927 | J35: ='Data Sheet'!I67/'Data Sheet'!I$75 -> 0.047024716 | ... L35: ='Data Sheet'!K67/'Data Sheet'!K$75 -> 0.0351431
B36: ='Data Sheet'!A68 -> Inventory | C36: ='Data Sheet'!B68/'Data Sheet'!B$75 -> 0.12407941 | D36: ='Data Sheet'!C68/'Data Sheet'!C$75 -> 0.12871547 | E36: ='Data Sheet'!D68/'Data Sheet'!D$75 -> 0.12878571 | F36: ='Data Sheet'!E68/'Data Sheet'!E$75 -> 0.12761951 | G36: ='Data Sheet'!F68/'Data Sheet'!F$75 -> 0.11698717 | H36: ='Data Sheet'!G68/'Data Sheet'!G$75 -> 0.10565506 | I36: ='Data Sheet'!H68/'Data Sheet'!H$75 -> 0.10709348 | J36: ='Data Sheet'!I68/'Data Sheet'!I$75 -> 0.12177623 | ... L36: ='Data Sheet'!K68/'Data Sheet'!K$75 -> 0.12539094
B37: ='Data Sheet'!A69 -> Cash & Bank | C37: ='Data Sheet'!B69/'Data Sheet'!B$75 -> 0.11573799 | D37: ='Data Sheet'!C69/'Data Sheet'!C$75 -> 0.13235686 | E37: ='Data Sheet'!D69/'Data Sheet'!D$75 -> 0.10579088 | F37: ='Data Sheet'!E69/'Data Sheet'!E$75 -> 0.10679898 | G37: ='Data Sheet'!F69/'Data Sheet'!F$75 -> 0.10533773 | H37: ='Data Sheet'!G69/'Data Sheet'!G$75 -> 0.13699234 | I37: ='Data Sheet'!H69/'Data Sheet'!H$75 -> 0.12359146 | J37: ='Data Sheet'!I69/'Data Sheet'!I$75 -> 0.1106017 | ... L37: ='Data Sheet'!K69/'Data Sheet'!K$75 -> 0.10832076
B39: Total Asset | C39: ='Data Sheet'!B75/'Data Sheet'!B$75 -> 1 | D39: ='Data Sheet'!C75/'Data Sheet'!C$75 -> 1 | E39: ='Data Sheet'!D75/'Data Sheet'!D$75 -> 1 | F39: ='Data Sheet'!E75/'Data Sheet'!E$75 -> 1 | G39: ='Data Sheet'!F75/'Data Sheet'!F$75 -> 1 | H39: ='Data Sheet'!G75/'Data Sheet'!G$75 -> 1 | I39: ='Data Sheet'!H75/'Data Sheet'!H$75 -> 1 | J39: ='Data Sheet'!I75/'Data Sheet'!I$75 -> 1 | ... L39: ='Data Sheet'!K75/'Data Sheet'!K$75 -> 1

Sheet Forcasting
B3: ='Data Sheet'!B1&" - "&'Data Sheet'!A17 -> TATA MOTORS LTD - Sales | G3: ='Data Sheet'!B1&" - "&HistoricaIFS!B17 -> TATA MOTORS LTD - EBITDA | L3: ='Data Sheet'!B1&" - "&HistoricaIFS!B37 -> TATA MOTORS LTD - EPS
B4: Year Weight | C4: Year | D4: Sales | E4: Sales Growth | G4: Year Weight | H4: Year | I4: EBITDA | J4: EBITDA Growth | L4: Year Weight | M4: Year | N4: EPS | O4: EPS Growth
B5: 1 | C5: 2016 | D5: {=TRANSPOSE('Data Sheet'!B17:K17)} -> 273045.6 | G5: 1 | H5: 2016 | I5: {=TRANSPOSE(HistoricaIFS!C17:L17)} -> 38395.25 | L5: 1 | M5: 2016 | N5: {=TRANSPOSE(HistoricaIFS!C37:L37)} -> 10.244216
B6: 2 | C6: 2017 | D6: 269692.51 | E6: =IFERROR(D6/D5-1,0) -> -0.01228033 | G6: 2 | H6: 2017 | I6: 29588.69 | J6: =IFERROR(I6/I5-1,0) -> -0.22936587 | L6: 2 | M6: 2017 | N6: 18.729574 | O6: =IFERROR(N6/N5-1,0) -> 0.82830727
B7: 3 | C7: 2018 | D7: 291550.48 | E7: =IFERROR(D7/D6-1,0) -> 0.081047746 | G7: 3 | H7: 2018 | I7: 31457.68 | J7: =IFERROR(I7/I6-1,0) -> 0.063165689 | L7: 3 | M7: 2018 | N7: 11.093409 | O7: =IFERROR(N7/N6-1,0) -> -0.40770629
B8: 4 | C8: 2019 | D8: 301938.4 | E8: =IFERROR(D8/D7-1,0) -> 0.035629919 | G8: 4 | H8: 2019 | I8: 24664.33 | J8: =IFERROR(I8/I7-1,0) -> -0.21595203 | L8: 4 | M8: 2019 | N8: 13.036401 | O8: =IFERROR(N8/N7-1,0) -> 0.1751483
